(py-yt-music-4l7U2eCV-py3.10) ~/p/g/py-yt-music|> invoke start
WARNING: [youtube:tab] YouTube said: INFO - 2 unavailable videos are hidden
WARNING: [youtube:tab] YouTube said: INFO - Unavailable videos will be hidden during playback
WARNING: [youtube:tab] YouTube said: INFO - 2 unavailable videos are hidden
WARNING: [youtube:tab] YouTube said: INFO - Unavailable videos will be hidden during playback
ERROR: [youtube] DYKOFBIrzGg: Video unavailable. This video contains content from KADOKAWA CORPORATION, who has blocked it on copyright grounds
Exception in thread Thread-2 (_download_thread_function):
Traceback (most recent call last):
  File "/home/bntti/.cache/pypoetry/virtualenvs/py-yt-music-4l7U2eCV-py3.10/lib/python3.10/site-packages/yt_dlp/extractor/common.py", line 642, in extract
    ie_result = self._real_extract(url)
  File "/home/bntti/.cache/pypoetry/virtualenvs/py-yt-music-4l7U2eCV-py3.10/lib/python3.10/site-packages/yt_dlp/extractor/youtube.py", line 3437, in _real_extract
    self.raise_no_formats(reason, expected=True)
  File "/home/bntti/.cache/pypoetry/virtualenvs/py-yt-music-4l7U2eCV-py3.10/lib/python3.10/site-packages/yt_dlp/extractor/common.py", line 1158, in raise_no_formats
    raise ExtractorError(msg, expected=expected, video_id=video_id)
yt_dlp.utils.ExtractorError: Video unavailable. This video contains content from KADOKAWA CORPORATION, who has blocked it on copyright grounds

During handling of the above exception, another exception occurred:

Traceback (most recent call last):
  File "/home/bntti/.cache/pypoetry/virtualenvs/py-yt-music-4l7U2eCV-py3.10/lib/python3.10/site-packages/yt_dlp/YoutubeDL.py", line 1395, in wrapper
    return func(self, *args, **kwargs)
  File "/home/bntti/.cache/pypoetry/virtualenvs/py-yt-music-4l7U2eCV-py3.10/lib/python3.10/site-packages/yt_dlp/YoutubeDL.py", line 1465, in __extract_info
    ie_result = ie.extract(url)
  File "/home/bntti/.cache/pypoetry/virtualenvs/py-yt-music-4l7U2eCV-py3.10/lib/python3.10/site-packages/yt_dlp/extractor/common.py", line 668, in extract
    raise type(e)(e.orig_msg, **kwargs)
yt_dlp.utils.ExtractorError: [youtube] DYKOFBIrzGg: Video unavailable. This video contains content from KADOKAWA CORPORATION, who has blocked it on copyright grounds

During handling of the above exception, another exception occurred:

Traceback (most recent call last):
  File "/usr/lib/python3.10/threading.py", line 1016, in _bootstrap_inner
    self.run()
  File "/usr/lib/python3.10/threading.py", line 953, in run
    self._target(*self._args, **self._kwargs)
  File "/home/bntti/programming/git-projects/py-yt-music/src/ui/download_view.py", line 66, in _download_thread_function
    playlist_manager_service.download_missing_songs(self._status)
  File "/home/bntti/programming/git-projects/py-yt-music/src/services/playlist_manager_service.py", line 115, in download_missing_songs
    self._song_service.download_song(song, status)
  File "/home/bntti/programming/git-projects/py-yt-music/src/services/song_service.py", line 33, in download_song
    path = self._youtube_api_service.download_song(song)
  File "/home/bntti/programming/git-projects/py-yt-music/src/services/youtube_api_service.py", line 55, in download_song
    song_data = ydl.extract_info(song.url)
  File "/home/bntti/.cache/pypoetry/virtualenvs/py-yt-music-4l7U2eCV-py3.10/lib/python3.10/site-packages/yt_dlp/YoutubeDL.py", line 1386, in extract_info
    return self.__extract_info(url, self.get_info_extractor(ie_key), download, extra_info, process)
  File "/home/bntti/.cache/pypoetry/virtualenvs/py-yt-music-4l7U2eCV-py3.10/lib/python3.10/site-packages/yt_dlp/YoutubeDL.py", line 1413, in wrapper
    self.report_error(str(e), e.format_traceback())
  File "/home/bntti/.cache/pypoetry/virtualenvs/py-yt-music-4l7U2eCV-py3.10/lib/python3.10/site-packages/yt_dlp/YoutubeDL.py", line 936, in report_error
    self.trouble(f'{self._format_err("ERROR:", self.Styles.ERROR)} {message}', *args, **kwargs)
  File "/home/bntti/.cache/pypoetry/virtualenvs/py-yt-music-4l7U2eCV-py3.10/lib/python3.10/site-packages/yt_dlp/YoutubeDL.py", line 879, in trouble
    raise DownloadError(message, exc_info)
yt_dlp.utils.DownloadError: ERROR: [youtube] DYKOFBIrzGg: Video unavailable. This video contains content from KADOKAWA CORPORATION, who has blocked it on copyright grounds

